Workbook

Sheet Capa e Instruções
A1: 📡 Homologação de Documentação — Redes Sem-Fio / Kali Linux
A2: Planilha de acompanhamento da aplicação prática dos procedimentos (Aulas 01-09) com equipamentos reais
B4: Curso / Turma:
B5: Instrutor responsável:
B6: Data de início da homologação:
B7: Versão da documentação avaliada:
B9: Como usar esta planilha
B10: 1. Aba 'Inventário' — cadastre os equipamentos (APs, antenas, notebooks) atribuídos a cada grupo antes da aula.
B11: 2. Aba 'Checklist Config (Aulas 01-05)' — marque o status de cada item de configuração dos Access Points, por grupo.
B12: 3. Aba 'Baseline Wireless' — preencha com os dados coletados na aula de reconhecimento passivo (BSSID, canal, PWR, etc.).
B13: 4. Aba 'Ataques - Resultados' — registre o resultado de cada ataque prático (WEP, WPS, WPA/WPA2, WPA3), por grupo.
B14: 5. Aba 'Dashboard' — visão consolidada com contagens automáticas (não editar; atualiza sozinha a partir das outras abas).
B15: 6. Aba 'Não Conformidades' — registre divergências entre o que está documentado (.md) e o que aconteceu na prática — isso alimenta a próxima revisão dos arquivos.
B17: Legenda de cores:
C18: Célula a preencher pelo grupo/instrutor
C19: Status: OK / concluído
C20: Status: Pendente / atenção
C21: Status: Falhou / não conformidade
B23: Esta planilha acompanha os arquivos .md do repositório (01-accesspoint, 02-installkali, 03-analytics, 04-aircrack-ng, 05-wordlist). Use-a durante a homologação prática para confirmar se cada procedimento descrito funciona como documentado nos equipamentos reais (TP-Link Archer C50(W), EC220-G5 e AX12).

Sheet Dashboard
A1: 📊 Dashboard — Visão Consolidada da Homologação
A2: Atualizado automaticamente a partir das abas 'Checklist Config' e 'Ataques - Resultados'. Não editar manualmente.
A4: Checklist de Configuração (Aulas 01-05)
A5: Métrica | B5: Total | C5: OK | D5: Pendente | E5: Falhou | F5: % Concluído
A6: Itens de configuração (todos os grupos) | B6: =COUNTA('Checklist Config (Aulas 01-05)'!D5:D304) -> 300 | C6: =COUNTIF('Checklist Config (Aulas 01-05)'!D5:D304,"OK") -> 0 | D6: =COUNTIF('Checklist Config (Aulas 01-05)'!D5:D304,"Pendente") -> 300 | E6: =COUNTIF('Checklist Config (Aulas 01-05)'!D5:D304,"Falhou") -> 0 | F6: =IFERROR(C6/B6,0) -> 0
A8: Ataques Práticos (Aulas 06-09)
A9: Métrica | B9: Total | C9: OK | D9: Pendente | E9: Falhou | F9: % Concluído
A10: Testes de ataque (todos os grupos) | B10: =COUNTA('Ataques - Resultados'!K5:K64) -> 60 | C10: =COUNTIF('Ataques - Resultados'!K5:K64,"OK") -> 0 | D10: =COUNTIF('Ataques - Resultados'!K5:K64,"Pendente") -> 60 | E10: =COUNTIF('Ataques - Resultados'!K5:K64,"Falhou") -> 0 | F10: =IFERROR(C10/B10,0) -> 0
A12: Por Protocolo de Ataque
A13: Protocolo | B13: Total testes | C13: OK | D13: Pendente | E13: Falhou | F13: % Sucesso
A14: WEP | B14: =COUNTIF('Ataques - Resultados'!C5:C64,"WEP") -> 10 | C14: =SUMPRODUCT(('Ataques - Resultados'!C5:C64="WEP")*('Ataques - Resultados'!K5:K64="OK")) -> 0 | D14: =SUMPRODUCT(('Ataques - Resultados'!C5:C64="WEP")*('Ataques - Resultados'!K5:K64="Pendente")) -> 10 | E14: =SUMPRODUCT(('Ataques - Resultados'!C5:C64="WEP")*('Ataques - Resultados'!K5:K64="Falhou")) -> 0 | F14: =IFERROR(C14/B14,0) -> 0
A15: WPS | B15: =COUNTIF('Ataques - Resultados'!C5:C64,"WPS") -> 10 | C15: =SUMPRODUCT(('Ataques - Resultados'!C5:C64="WPS")*('Ataques - Resultados'!K5:K64="OK")) -> 0 | D15: =SUMPRODUCT(('Ataques - Resultados'!C5:C64="WPS")*('Ataques - Resultados'!K5:K64="Pendente")) -> 10 | E15: =SUMPRODUCT(('Ataques - Resultados'!C5:C64="WPS")*('Ataques - Resultados'!K5:K64="Falhou")) -> 0 | F15: =IFERROR(C15/B15,0) -> 0
A16: WPA/WPA2-PSK (AES) | B16: =COUNTIF('Ataques - Resultados'!C5:C64,"WPA/WPA2-PSK (AES)") -> 10 | C16: =SUMPRODUCT(('Ataques - Resultados'!C5:C64="WPA/WPA2-PSK (AES)")*('Ataques - Resultados'!K5:K64="OK")) -> 0 | D16: =SUMPRODUCT(('Ataques - Resultados'!C5:C64="WPA/WPA2-PSK (AES)")*('Ataques - Resultados'!K5:K64="Pendente")) -> 10 | E16: =SUMPRODUCT(('Ataques - Resultados'!C5:C64="WPA/WPA2-PSK (AES)")*('Ataques - Resultados'!K5:K64="Falhou")) -> 0 | F16: =IFERROR(C16/B16,0) -> 0
A17: WPA/WPA2-PSK (AES+TKIP) | B17: =COUNTIF('Ataques - Resultados'!C5:C64,"WPA/WPA2-PSK (AES+TKIP)") -> 10 | C17: =SUMPRODUCT(('Ataques - Resultados'!C5:C64="WPA/WPA2-PSK (AES+TKIP)")*('Ataques - Resultados'!K5:K64="OK")) -> 0 | D17: =SUMPRODUCT(('Ataques - Resultados'!C5:C64="WPA/WPA2-PSK (AES+TKIP)")*('Ataques - Resultados'!K5:K64="Pendente")) -> 10 | E17: =SUMPRODUCT(('Ataques - Resultados'!C5:C64="WPA/WPA2-PSK (AES+TKIP)")*('Ataques - Resultados'!K5:K64="Falhou")) -> 0 | F17: =IFERROR(C17/B17,0) -> 0
A18: WPA3-SAE puro (Cenário A) | B18: =COUNTIF('Ataques - Resultados'!C5:C64,"WPA3-SAE puro (Cenário A)") -> 10 | C18: =SUMPRODUCT(('Ataques - Resultados'!C5:C64="WPA3-SAE puro (Cenário A)")*('Ataques - Resultados'!K5:K64="OK")) -> 0 | D18: =SUMPRODUCT(('Ataques - Resultados'!C5:C64="WPA3-SAE puro (Cenário A)")*('Ataques - Resultados'!K5:K64="Pendente")) -> 10 | E18: =SUMPRODUCT(('Ataques - Resultados'!C5:C64="WPA3-SAE puro (Cenário A)")*('Ataques - Resultados'!K5:K64="Falhou")) -> 0 | F18: =IFERROR(C18/B18,0) -> 0
A19: WPA2/WPA3 downgrade (Cenário B) | B19: =COUNTIF('Ataques - Resultados'!C5:C64,"WPA2/WPA3 downgrade (Cenário B)") -> 10 | C19: =SUMPRODUCT(('Ataques - Resultados'!C5:C64="WPA2/WPA3 downgrade (Cenário B)")*('Ataques - Resultados'!K5:K64="OK")) -> 0 | D19: =SUMPRODUCT(('Ataques - Resultados'!C5:C64="WPA2/WPA3 downgrade (Cenário B)")*('Ataques - Resultados'!K5:K64="Pendente")) -> 10 | E19: =SUMPRODUCT(('Ataques - Resultados'!C5:C64="WPA2/WPA3 downgrade (Cenário B)")*('Ataques - Resultados'!K5:K64="Falhou")) -> 0 | F19: =IFERROR(C19/B19,0) -> 0
A21: Observação: os valores acima são calculados por fórmula (COUNTA/COUNTIF/SUMPRODUCT) a partir das abas 'Checklist Config (Aulas 01-05)' e 'Ataques - Resultados'. Atualize o status nessas abas — o Dashboard recalcula automaticamente.

Sheet Inventário
A1: 📋 Inventário de Equipamentos por Grupo
A2: Preencher antes do início da aula prática
A4: Grupo | B4: Modelo do AP | C4: Nº patrimônio / etiqueta | D4: Notebook (hostname) | E4: Antena externa (modelo/chipset) | F4: Interface (wlanX) | G4: Responsável pelo grupo | H4: Observações
A5: Grupo 01
A6: Grupo 02
A7: Grupo 03
A8: Grupo 04
A9: Grupo 05
A10: Grupo 06
A11: Grupo 07
A12: Grupo 08
A13: Grupo 09
A14: Grupo 10

Sheet Checklist Config (Aulas 01-05)
A1: ✅ Checklist de Configuração — Aulas 01 a 05 (Access Points TP-Link)
A2: Um bloco de linhas por grupo. Selecione o Status na lista suspensa.
A4: Grupo | B4: Aula / Módulo | C4: Item do checklist | D4: Status | E4: Responsável | F4: Data | G4: Observações
A5: Grupo 01 | B5: Aula 01 — Reset e Config. Básica | C5: Reset de fábrica realizado com sucesso | D5: Pendente
B6: Aula 01 — Reset e Config. Básica | C6: Conexão de rede testada via ping (192.168.0.1) | D6: Pendente
B7: Aula 01 — Reset e Config. Básica | C7: Acesso à interface web realizado e senha de admin definida | D7: Pendente
B8: Aula 01 — Reset e Config. Básica | C8: Fuso horário configurado (Brasília — UTC-03:00) | D8: Pendente
B9: Aula 01 — Reset e Config. Básica | C9: WAN em IP Dinâmico configurada | D9: Pendente
B10: Aula 01 — Reset e Config. Básica | C10: WLAN 2.4/5.0 GHz desabilitadas propositalmente no wizard | D10: Pendente
B11: Aula 02 — WAN e LAN | C11: DNS da WAN configurado com servidor de proteção familiar | D11: Pendente
B12: Aula 02 — WAN e LAN | C12: Hostname (ap-grupo-0X) definido corretamente | D12: Pendente
B13: Aula 02 — WAN e LAN | C13: IP da LAN alterado para 172.16.xxx.254/24 | D13: Pendente
B14: Aula 02 — WAN e LAN | C14: Placa de rede do computador reconfigurada para a nova faixa | D14: Pendente
B15: Aula 02 — WAN e LAN | C15: DHCP habilitado com pool 172.16.xxx.100–150 | D15: Pendente
B16: Aula 02 — WAN e LAN | C16: Gateway e DNS primário do DHCP apontando para 172.16.xxx.254 | D16: Pendente
B17: Aula 02 — WAN e LAN | C17: Servidores NTP (a.st1.ntp.br / c.st1.ntp.br) configurados | D17: Pendente
... B34: Aula 05 — Monitoramento e Acesso | C34: Perfil de Controle dos Pais criado e testado | D34: Pendente
A35: Grupo 02 | B35: Aula 01 — Reset e Config. Básica | C35: Reset de fábrica realizado com sucesso | D35: Pendente
B36: Aula 01 — Reset e Config. Básica | C36: Conexão de rede testada via ping (192.168.0.1) | D36: Pendente
B37: Aula 01 — Reset e Config. Básica | C37: Acesso à interface web realizado e senha de admin definida | D37: Pendente
B38: Aula 01 — Reset e Config. Básica | C38: Fuso horário configurado (Brasília — UTC-03:00) | D38: Pendente
B39: Aula 01 — Reset e Config. Básica | C39: WAN em IP Dinâmico configurada | D39: Pendente
B40: Aula 01 — Reset e Config. Básica | C40: WLAN 2.4/5.0 GHz desabilitadas propositalmente no wizard | D40: Pendente
B41: Aula 02 — WAN e LAN | C41: DNS da WAN configurado com servidor de proteção familiar | D41: Pendente
B42: Aula 02 — WAN e LAN | C42: Hostname (ap-grupo-0X) definido corretamente | D42: Pendente
B43: Aula 02 — WAN e LAN | C43: IP da LAN alterado para 172.16.xxx.254/24 | D43: Pendente
B44: Aula 02 — WAN e LAN | C44: Placa de rede do computador reconfigurada para a nova faixa | D44: Pendente
B45: Aula 02 — WAN e LAN | C45: DHCP habilitado com pool 172.16.xxx.100–150 | D45: Pendente
B46: Aula 02 — WAN e LAN | C46: Gateway e DNS primário do DHCP apontando para 172.16.xxx.254 | D46: Pendente
B47: Aula 02 — WAN e LAN | C47: Servidores NTP (a.st1.ntp.br / c.st1.ntp.br) configurados | D47: Pendente
... B64: Aula 05 — Monitoramento e Acesso | C64: Perfil de Controle dos Pais criado e testado | D64: Pendente
A65: Grupo 03 | B65: Aula 01 — Reset e Config. Básica | C65: Reset de fábrica realizado com sucesso | D65: Pendente
B66: Aula 01 — Reset e Config. Básica | C66: Conexão de rede testada via ping (192.168.0.1) | D66: Pendente
B67: Aula 01 — Reset e Config. Básica | C67: Acesso à interface web realizado e senha de admin definida | D67: Pendente
B68: Aula 01 — Reset e Config. Básica | C68: Fuso horário configurado (Brasília — UTC-03:00) | D68: Pendente
B69: Aula 01 — Reset e Config. Básica | C69: WAN em IP Dinâmico configurada | D69: Pendente
B70: Aula 01 — Reset e Config. Básica | C70: WLAN 2.4/5.0 GHz desabilitadas propositalmente no wizard | D70: Pendente
B71: Aula 02 — WAN e LAN | C71: DNS da WAN configurado com servidor de proteção familiar | D71: Pendente
B72: Aula 02 — WAN e LAN | C72: Hostname (ap-grupo-0X) definido corretamente | D72: Pendente
B73: Aula 02 — WAN e LAN | C73: IP da LAN alterado para 172.16.xxx.254/24 | D73: Pendente
...

Sheet Baseline Wireless
A1: 📶 Baseline do Ambiente Sem-Fio (Reconhecimento Passivo)
A2: Preencher com base na aula de Análise do Ambiente Wireless, antes dos ataques
A4: Grupo | B4: Hostname notebook | C4: Interface(s) sem-fio | D4: Antena (modelo/chipset) | E4: BSSID do AP | F4: ESSID (2.4 / 5.0 GHz) | G4: Canal(is) | H4: Largura de canal | I4: ENC / CIPHER / AUTH | J4: PWR médio (dBm) | K4: APs vizinhos no mesmo canal | L4: Cliente teste (MAC) | M4: Observações / interferência
A5: Grupo 01
A6: Grupo 02
A7: Grupo 03
A8: Grupo 04
A9: Grupo 05
A10: Grupo 06
A11: Grupo 07
A12: Grupo 08
A13: Grupo 09
A14: Grupo 10

Sheet Ataques - Resultados
A1: 🎯 Resultados dos Ataques Práticos (Aulas 06 a 09)
A2: WEP, WPS, WPA/WPA2-PSK e WPA3-SAE — um bloco de linhas por grupo
A4: Grupo | B4: Aula | C4: Protocolo | D4: BSSID alvo | E4: Canal | F4: Ferramenta principal | G4: Senha / PIN encontrado | H4: IVs / tentativas | I4: Tempo total (min) | J4: Data do teste | K4: Status | L4: Observações
A5: Grupo 01 | B5: Aula 06 | C5: WEP | F5: aircrack-ng (IVs) | K5: Pendente
B6: Aula 07 | C6: WPS | F6: reaver / pixiewps | K6: Pendente
B7: Aula 08 | C7: WPA/WPA2-PSK (AES) | F7: aircrack-ng / hashcat | K7: Pendente
B8: Aula 08 | C8: WPA/WPA2-PSK (AES+TKIP) | F8: aircrack-ng / hashcat | K8: Pendente
B9: Aula 09 | C9: WPA3-SAE puro (Cenário A) | F9: N/A — demonstrativo | K9: Pendente
B10: Aula 09 | C10: WPA2/WPA3 downgrade (Cenário B) | F10: aircrack-ng / hashcat | K10: Pendente
A11: Grupo 02 | B11: Aula 06 | C11: WEP | F11: aircrack-ng (IVs) | K11: Pendente
B12: Aula 07 | C12: WPS | F12: reaver / pixiewps | K12: Pendente
B13: Aula 08 | C13: WPA/WPA2-PSK (AES) | F13: aircrack-ng / hashcat | K13: Pendente
B14: Aula 08 | C14: WPA/WPA2-PSK (AES+TKIP) | F14: aircrack-ng / hashcat | K14: Pendente
B15: Aula 09 | C15: WPA3-SAE puro (Cenário A) | F15: N/A — demonstrativo | K15: Pendente
B16: Aula 09 | C16: WPA2/WPA3 downgrade (Cenário B) | F16: aircrack-ng / hashcat | K16: Pendente
A17: Grupo 03 | B17: Aula 06 | C17: WEP | F17: aircrack-ng (IVs) | K17: Pendente
B18: Aula 07 | C18: WPS | F18: reaver / pixiewps | K18: Pendente
B19: Aula 08 | C19: WPA/WPA2-PSK (AES) | F19: aircrack-ng / hashcat | K19: Pendente
B20: Aula 08 | C20: WPA/WPA2-PSK (AES+TKIP) | F20: aircrack-ng / hashcat | K20: Pendente
B21: Aula 09 | C21: WPA3-SAE puro (Cenário A) | F21: N/A — demonstrativo | K21: Pendente
B22: Aula 09 | C22: WPA2/WPA3 downgrade (Cenário B) | F22: aircrack-ng / hashcat | K22: Pendente
A23: Grupo 04 | B23: Aula 06 | C23: WEP | F23: aircrack-ng (IVs) | K23: Pendente
B24: Aula 07 | C24: WPS | F24: reaver / pixiewps | K24: Pendente
B25: Aula 08 | C25: WPA/WPA2-PSK (AES) | F25: aircrack-ng / hashcat | K25: Pendente
B26: Aula 08 | C26: WPA/WPA2-PSK (AES+TKIP) | F26: aircrack-ng / hashcat | K26: Pendente
B27: Aula 09 | C27: WPA3-SAE puro (Cenário A) | F27: N/A — demonstrativo | K27: Pendente
B28: Aula 09 | C28: WPA2/WPA3 downgrade (Cenário B) | F28: aircrack-ng / hashcat | K28: Pendente
A29: Grupo 05 | B29: Aula 06 | C29: WEP | F29: aircrack-ng (IVs) | K29: Pendente
B30: Aula 07 | C30: WPS | F30: reaver / pixiewps | K30: Pendente
B31: Aula 08 | C31: WPA/WPA2-PSK (AES) | F31: aircrack-ng / hashcat | K31: Pendente
B32: Aula 08 | C32: WPA/WPA2-PSK (AES+TKIP) | F32: aircrack-ng / hashcat | K32: Pendente
B33: Aula 09 | C33: WPA3-SAE puro (Cenário A) | F33: N/A — demonstrativo | K33: Pendente
B34: Aula 09 | C34: WPA2/WPA3 downgrade (Cenário B) | F34: aircrack-ng / hashcat | K34: Pendente
A35: Grupo 06 | B35: Aula 06 | C35: WEP | F35: aircrack-ng (IVs) | K35: Pendente
B36: Aula 07 | C36: WPS | F36: reaver / pixiewps | K36: Pendente
B37: Aula 08 | C37: WPA/WPA2-PSK (AES) | F37: aircrack-ng / hashcat | K37: Pendente
B38: Aula 08 | C38: WPA/WPA2-PSK (AES+TKIP) | F38: aircrack-ng / hashcat | K38: Pendente
B39: Aula 09 | C39: WPA3-SAE puro (Cenário A) | F39: N/A — demonstrativo | K39: Pendente
B40: Aula 09 | C40: WPA2/WPA3 downgrade (Cenário B) | F40: aircrack-ng / hashcat | K40: Pendente
A41: Grupo 07 | B41: Aula 06 | C41: WEP | F41: aircrack-ng (IVs) | K41: Pendente
...

Sheet Não Conformidades
A1: 🛠️ Registro de Não Conformidades e Sugestões de Atualização
A2: Toda divergência entre o .md e a prática deve virar uma linha aqui — alimenta a próxima revisão da documentação
A4: Nº | B4: Arquivo .md / Aula | C4: Seção / Passo | D4: O que a documentação diz | E4: O que aconteceu na prática | F4: Ação sugerida | G4: Responsável | H4: Status
A5: 1 | B5: 04-aircrack-ng/09 (WPA3) | C5: Cabeçalho / equipamento | D5: Aula usa Archer AX12, diferente das Aulas 01-08 (C50/EC220-G5) | F5: Confirmar disponibilidade de AX12 suficiente para todos os grupos | H5: Pendente
A6: 2 | B6: 01-accesspoint/05 (Monitoramento) | C6: Item 09 - Controle dos Pais | D6: Procedimento descrito como incompleto na documentação original | F6: Completar passo a passo do cadastro de perfil antes da aula | H6: Pendente
A7: 3 | B7: 05-wordlist/02-expandida.txt | C7: Sufixos de ano | D7: Algumas entradas parecem concatenadas incorretamente (ex.: Senactit@1232024) | F7: Revisar script gerador da wordlist expandida | H7: Pendente
A8: 4
A9: 5
A10: 6
A11: 7
A12: 8
A13: 9
A14: 10
A15: 11
A16: 12
A17: 13
A18: 14
A19: 15
... A22: 18
